Workbook
Name iIndustry: '[1]Step 1 - Fill in Details'!$Q$18
Name iIndustry: 'Step 1 - Fill in Details'!$Q$18
Name iTechnology: '[1]Step 1 - Fill in Details'!$Q$8
Name iTechnology: 'Step 1 - Fill in Details'!$Q$8
Name ToSort: #REF!

Sheet GARTNER LEADER'S TOOL
B11: Unless otherwise marked for external use, the items in this Gartner Tool are for internal noncommercial use by the licensed Gartner client. The materials contained in this Tool may not be repackaged or resold. Gartner makes no representations or warranties as to the suitability of this Tool for any particular purpose, and disclaims all liabilities for any damages, whether direct, consequential, incidental or special, arising out of the use of or inability to use this material or the information provided herein.
B13: The instructions, intent and objective of this template are contained in the source document. Please refer to that document for details.

Sheet Step 0 - About Prism
B6: Table of Contents
B9: Step 1 - Fill in Details | D9: INPUT: This sheet should be filled in with the use cases in-scope, the dimensions that will aggregate up position based on business value and feasibility (weightings can also be adjusted on this sheet), and the project title and domain if required.
B10: Step 2 - Scoring | D10: INPUT: This sheet is used to input / update the scores for each use case in-scope.
B11: Step 3 - Create Pipeline | D11: INPUT: This sheet allows users to map use cases against a relevant pipeline or workflow if required.
B12: (VIEW) Symbol Sheet | D12: READ-ONLY: This sheet should be filled in with the use cases in-scope, the dimensions that will aggregate up position based on business value and feasibility, and the project title and domain if required.
B13: (VIEW) Prism | D13: READ-ONLY: This sheet should be filled in with the use cases in-scope, the dimensions that will aggregate up position based on business value and feasibility, and the project title and domain if required.
B17: Additional information and resources
B20: Overview of Gartner Prisms | D20: A directory of all resources related to Prisms, including a library of published Prisms and additional supporting material for project managers, sponsors and contributors.
B21: Toolkit Slides: Build Your Own Prism

Sheet Step 1 - Fill in Details
C3: Title | E3: Infographic: AI Use Case Prism for XYZ
C4: Short Description | E4: This infographic identifies NN of the most prominent AI use cases that can improve XYZ. Data and analytics leaders in XYZ can use this as a starting point for further fine-tuning.
K5: Values must sum to 100%
C6: Use Case Name | E6: Use Case Description
B7: UC1 | C7: Example Use Case 1 | D7: =AND(C7<>B7,NOT(ISBLANK(C7))) -> TRUE | L7: Business Value | Q7: Technology
B8: UC2 | C8: Example Use Case 2 | D8: =AND(C8<>B8,NOT(ISBLANK(C8))) -> TRUE | L8: Dimension | M8: Weight
B9: UC3 | C9: UC3 | D9: =AND(C9<>B9,NOT(ISBLANK(C9))) -> FALSE | J9: =COUNTIF($N$9:N9,FALSE()) -> 1 | K9: D1 | L9: Cost Reduction | M9: 0.3 | N9: =K9=L9 -> FALSE | P9: D1 | S9: =P9=Q9 -> FALSE
B10: UC4 | C10: UC4 | D10: =AND(C10<>B10,NOT(ISBLANK(C10))) -> FALSE | J10: =COUNTIF($N$9:N10,FALSE()) -> 2 | K10: D2 | L10: Revenue Optimization | M10: 0.4 | N10: =K10=L10 -> FALSE | P10: D2 | S10: =P10=Q10 -> FALSE
B11: UC5 | C11: UC5 | D11: =AND(C11<>B11,NOT(ISBLANK(C11))) -> FALSE | J11: =COUNTIF($N$9:N11,FALSE()) -> 3 | K11: D3 | L11: CX Improvement | M11: 0.3 | N11: =K11=L11 -> FALSE | P11: D3 | S11: =P11=Q11 -> FALSE
B12: UC6 | C12: UC6 | D12: =AND(C12<>B12,NOT(ISBLANK(C12))) -> FALSE | J12: =COUNTIF($N$9:N12,FALSE()) -> 3 | K12: D4 | L12: D4 | N12: =K12=L12 -> TRUE | P12: D4 | S12: =P12=Q12 -> FALSE
B13: UC7 | C13: UC7 | D13: =AND(C13<>B13,NOT(ISBLANK(C13))) -> FALSE | J13: =COUNTIF($N$9:N13,FALSE()) -> 3 | K13: D5 | L13: D5 | N13: =K13=L13 -> TRUE | P13: D5 | S13: =P13=Q13 -> FALSE
B14: UC8 | C14: UC8 | D14: =AND(C14<>B14,NOT(ISBLANK(C14))) -> FALSE | J14: =COUNTIF($N$9:N14,FALSE()) -> 3 | M14: =SUM(M9:M13) -> 1 | N14: =M14=1 -> TRUE
B15: UC9 | C15: UC9 | D15: =AND(C15<>B15,NOT(ISBLANK(C15))) -> FALSE | J15: =COUNTIF($N$9:N15,FALSE()) -> 3
B16: UC10 | C16: UC10 | D16: =AND(C16<>B16,NOT(ISBLANK(C16))) -> FALSE | J16: =COUNTIF($N$9:N16,FALSE()) -> 3
B17: UC11 | C17: UC11 | D17: =AND(C17<>B17,NOT(ISBLANK(C17))) -> FALSE | J17: =COUNTIF($N$9:N17,FALSE()) -> 3 | L17: Feasibility | Q17: Industry
B18: UC12 | C18: UC12 | D18: =AND(C18<>B18,NOT(ISBLANK(C18))) -> FALSE | J18: =COUNTIF($N$9:N18,FALSE()) -> 3 | L18: Dimension | M18: Weight | Q18: Lorem Ipsum
B19: UC13 | C19: UC13 | D19: =AND(C19<>B19,NOT(ISBLANK(C19))) -> FALSE | J19: =COUNTIF($N$9:N19,FALSE()) -> 4 | K19: D1 | L19: Technical | M19: 0.3 | N19: =K19=L19 -> FALSE | P19: D1 | S19: =P19=Q19 -> FALSE
B20: UC14 | C20: UC14 | D20: =AND(C20<>B20,NOT(ISBLANK(C20))) -> FALSE | J20: =COUNTIF($N$9:N20,FALSE()) -> 5 | K20: D2 | L20: Internal | M20: 0.4 | N20: =K20=L20 -> FALSE | P20: D2 | S20: =P20=Q20 -> FALSE
B21: UC15 | C21: UC15 | D21: =AND(C21<>B21,NOT(ISBLANK(C21))) -> FALSE | J21: =COUNTIF($N$9:N21,FALSE()) -> 6 | K21: D3 | L21: External | M21: 0.3 | N21: =K21=L21 -> FALSE | P21: D3 | S21: =P21=Q21 -> FALSE
B22: UC16 | C22: UC16 | D22: =AND(C22<>B22,NOT(ISBLANK(C22))) -> FALSE | J22: =COUNTIF($N$9:N22,FALSE()) -> 6 | K22: D4 | L22: D4 | N22: =K22=L22 -> TRUE | P22: D4 | S22: =P22=Q22 -> FALSE
B23: UC17 | C23: UC17 | D23: =AND(C23<>B23,NOT(ISBLANK(C23))) -> FALSE | J23: =COUNTIF($N$9:N23,FALSE()) -> 6 | K23: D5 | L23: D5 | N23: =K23=L23 -> TRUE | P23: D5 | S23: =P23=Q23 -> FALSE
B24: UC18 | C24: UC18 | D24: =AND(C24<>B24,NOT(ISBLANK(C24))) -> FALSE | M24: =SUM(M19:M23) -> 1 | N24: =M24=1 -> TRUE
B25: UC19 | C25: UC19 | D25: =AND(C25<>B25,NOT(ISBLANK(C25))) -> FALSE
B26: UC20 | C26: UC20 | D26: =AND(C26<>B26,NOT(ISBLANK(C26))) -> FALSE
B27: UC21 | C27: UC21 | D27: =AND(C27<>B27,NOT(ISBLANK(C27))) -> FALSE | K27: # | L27: Dimension | N27: Dimension Description
B28: UC22 | C28: UC22 | D28: =AND(C28<>B28,NOT(ISBLANK(C28))) -> FALSE | H28: =K28 -> 1 | I28: =J28=L28 -> FALSE | J28: D1 | K28: =INDEX($J$9:$L$23,MATCH(L28,$L$9:$L$23,0),1) -> 1 | L28: =L9 -> Cost Reduction | N28: Lorem ipso factum | S28: =K28 -> 1 | T28: =L28&" - "&N28 -> Cost Reduction - Lorem ipso factum
B29: UC23 | C29: UC23 | D29: =AND(C29<>B29,NOT(ISBLANK(C29))) -> FALSE | H29: =K29 -> 2 | I29: =J29=L29 -> FALSE | J29: D2 | K29: =INDEX($J$9:$L$23,MATCH(L29,$L$9:$L$23,0),1) -> 2 | L29: =L10 -> Revenue Optimization | N29: Lorem ipso factum | S29: =K29 -> 2 | T29: =L29&" - "&N29 -> Revenue Optimization - Lorem ipso factum
B30: UC24 | C30: UC24 | D30: =AND(C30<>B30,NOT(ISBLANK(C30))) -> FALSE | H30: =K30 -> 3 | I30: =J30=L30 -> FALSE | J30: D3 | K30: =INDEX($J$9:$L$23,MATCH(L30,$L$9:$L$23,0),1) -> 3 | L30: =L11 -> CX Improvement | N30: Lorem ipso factum | S30: =K30 -> 3 | T30: =L30&" - "&N30 -> CX Improvement - Lorem ipso factum
B31: UC25 | C31: UC25 | D31: =AND(C31<>B31,NOT(ISBLANK(C31))) -> FALSE | H31: =K31 -> 3 | I31: =J31=L31 -> TRUE | J31: D4 | K31: =INDEX($J$9:$L$23,MATCH(L31,$L$9:$L$23,0),1) -> 3 | L31: =L12 -> D4 | S31: =K31 -> 3 | T31: =L31&" - "&N31 -> D4 -
H32: =K32 -> 3 | I32: =J32=L32 -> TRUE | J32: D5 | K32: =INDEX($J$9:$L$23,MATCH(L32,$L$9:$L$23,0),1) -> 3 | L32: =L13 -> D5 | S32: =K32 -> 3 | T32: =L32&" - "&N32 -> D5 -
C33: Pipeline | E33: Description | H33: =K33 -> 4 | I33: =J33=L33 -> FALSE | J33: D1 | K33: =INDEX($J$9:$L$23,MATCH(L33,$L$9:$L$23,0),1) -> 4 | L33: =L19 -> Technical | N33: Lorem ipso factum | S33: =K33 -> 4 | T33: =L33&" - "&N33 -> Technical - Lorem ipso factum
B34: Pipeline Item #1 | C34: Example pipeline item | H34: =K34 -> 5 | I34: =J34=L34 -> FALSE | J34: D2 | K34: =INDEX($J$9:$L$23,MATCH(L34,$L$9:$L$23,0),1) -> 5 | L34: =L20 -> Internal | N34: Lorem ipso factum | S34: =K34 -> 5 | T34: =L34&" - "&N34 -> Internal - Lorem ipso factum
B35: Pipeline Item #2 | C35: Pipeline Item #2 | H35: =K35 -> 6 | I35: =J35=L35 -> FALSE | J35: D3 | K35: =INDEX($J$9:$L$23,MATCH(L35,$L$9:$L$23,0),1) -> 6 | L35: =L21 -> External | N35: Lorem ipso factum | S35: =K35 -> 6 | T35: =L35&" - "&N35 -> External - Lorem ipso factum
B36: Pipeline Item #3 | C36: Pipeline Item #3 | H36: =K36 -> 3 | I36: =J36=L36 -> TRUE | J36: D4 | K36: =INDEX($J$9:$L$23,MATCH(L36,$L$9:$L$23,0),1) -> 3 | L36: =L22 -> D4 | S36: =K36 -> 3 | T36: =L36&" - "&N36 -> D4 -
B37: Pipeline Item #4 | C37: Pipeline Item #4 | H37: =K37 -> 3 | I37: =J37=L37 -> TRUE | J37: D5 | K37: =INDEX($J$9:$L$23,MATCH(L37,$L$9:$L$23,0),1) -> 3 | L37: =L23 -> D5 | S37: =K37 -> 3 | T37: =L37&" - "&N37 -> D5 -
B38: Pipeline Item #5 | C38: Pipeline Item #5
B39: Pipeline Item #6 | C39: Pipeline Item #6

Sheet Step 2 - Scoring
A2: Sum of either the business value factors or feasibility value factors is not equal to 100% - Please go back to Step 1. | C2: No Contribution | D2: Low Contribution | E2: Medium Contribution | F2: High Contribution | G2: Outstanding Contribuion | I2: Impossible | J2: Challenging | K2: Complicated | L2: Doable | M2: Easy
C3: 0 | D3: 1 | E3: 2 | F3: 3 | G3: 4 | I3: 0 | J3: 1 | K3: 2 | L3: 3 | M3: 4
C4: =NOT('Step 1 - Fill in Details'!$N$9) -> TRUE | D4: =NOT('Step 1 - Fill in Details'!$N$10) -> TRUE | E4: =NOT('Step 1 - Fill in Details'!$N$11) -> TRUE | F4: =NOT('Step 1 - Fill in Details'!$N12) -> FALSE | G4: =NOT('Step 1 - Fill in Details'!$N$13) -> FALSE | I4: =NOT('Step 1 - Fill in Details'!$N$19) -> TRUE | J4: =NOT('Step 1 - Fill in Details'!$N$20) -> TRUE | K4: =NOT('Step 1 - Fill in Details'!$N$21) -> TRUE | L4: =NOT('Step 1 - Fill in Details'!$N$22) -> FALSE | M4: =NOT('Step 1 - Fill in Details'!$N$23) -> FALSE
C5: =iTechnology&" use cases in "&iIndustry&" industry" -> use cases in Lorem Ipsum industry
C7: Business Value | I7: Feasibility | O7: Rankings
C8: =SUM(C10:G10)=1 -> TRUE | I8: =SUM(I10:M10)=1 -> TRUE
C9: =IF(NOT('Step 1 - Fill in Details'!N9),'Step 1 - Fill in Details'!L9,"") -> Cost Reduction | D9: =IF(NOT('Step 1 - Fill in Details'!N10),'Step 1 - Fill in Details'!L10,"") -> Revenue Optimization | E9: =IF(NOT('Step 1 - Fill in Details'!N11),'Step 1 - Fill in Details'!L11,"") -> CX Improvement | F9: =IF(NOT('Step 1 - Fill in Details'!N12),'Step 1 - Fill in Details'!L12,"") | G9: =IF(NOT('Step 1 - Fill in Details'!N13),'Step 1 - Fill in Details'!L13,"") | I9: =IF(NOT('Step 1 - Fill in Details'!N19),'Step 1 - Fill in Details'!L19,"") -> Technical | J9: =IF(NOT('Step 1 - Fill in Details'!N20),'Step 1 - Fill in Details'!L20,"") -> Internal | K9: =IF(NOT('Step 1 - Fill in Details'!N21),'Step 1 - Fill in Details'!L21,"") -> External | L9: =IF(NOT('Step 1 - Fill in Details'!N22),'Step 1 - Fill in Details'!L22,"") | M9: =IF(NOT('Step 1 - Fill in Details'!N23),'Step 1 - Fill in Details'!L23,"") | O9: Business Value | P9: Feasibility Value
A10: Weights | C10: =IF(NOT('Step 1 - Fill in Details'!N9),'Step 1 - Fill in Details'!M9,0) -> 0.3 | D10: =IF(NOT('Step 1 - Fill in Details'!N10),'Step 1 - Fill in Details'!M10,0) -> 0.4 | E10: =IF(NOT('Step 1 - Fill in Details'!N11),'Step 1 - Fill in Details'!M11,0) -> 0.3 | F10: =IF(NOT('Step 1 - Fill in Details'!N12),'Step 1 - Fill in Details'!M12,0) -> 0 | G10: =IF(NOT('Step 1 - Fill in Details'!N13),'Step 1 - Fill in Details'!M13,0) -> 0 | I10: =IF(NOT('Step 1 - Fill in Details'!N19),'Step 1 - Fill in Details'!M19,0) -> 0.3 | J10: =IF(NOT('Step 1 - Fill in Details'!N20),'Step 1 - Fill in Details'!M20,0) -> 0.4 | K10: =IF(NOT('Step 1 - Fill in Details'!N21),'Step 1 - Fill in Details'!M21,0) -> 0.3 | L10: =IF(NOT('Step 1 - Fill in Details'!N22),'Step 1 - Fill in Details'!M22,0) -> 0 | M10: =IF(NOT('Step 1 - Fill in Details'!N23),'Step 1 - Fill in Details'!M23,0) -> 0
A11: ='Step 1 - Fill in Details'!C7 -> Example Use Case 1 | B11: ='Step 1 - Fill in Details'!D7 -> TRUE | C11: 4 | D11: 0 | E11: 4 | I11: NA | J11: 2 | K11: 1 | O11: =AX11 -> 2.4 | P11: =AY11 -> 1.5714286 | Q11: {=P11+O11+(RAND()*0.00000000000001+1/ROW(1:1)*0.000001)} -> 3.9714296 | R11: =AND(P11=0,O11=0) -> FALSE | S11: {=SUMPRODUCT(($R$11:R11)*1)} -> 0 | U11: =AND(O11=0,P11=0) -> FALSE | V11: {=SUMPRODUCT(($U$10:U11)*1)} -> 0 | X11: {=SUMPRODUCT($I$10:$M$10,(I11:M11<>"NA")*1)} -> 0.7 | Y11: =IF(I11="NA",0,I$10/$X11) -> 0 | Z11: =IF(J11="NA",0,J$10/$X11) -> 0.57142857 | AA11: =IF(K11="NA",0,K$10/$X11) -> 0.42857143 | AB11: =IF(L11="NA",0,L$10/$X11) -> 0 | AC11: =IF(M11="NA",0,M$10/$X11) -> 0 | AD11: =IF(X11<1, AE11, "") -> Readjusted weights: :57.1428571428572% :42.8571428571429% in this use case because has/have NA values in it | AE11: =CONCATENATE("Readjusted weights: ", IF(Y11=0, " ", CONCATENATE($J$8, ":", Y11*100, "% ")), IF(Z11=0, " ", CONCATENATE($K$8, ":", Z11*100, "% ")), IF(AA11=0, " ", CONCATENATE($L$8, ":", AA11*100, "% ")), IF(AB11=0, " ", CONCATENATE($M$8, ":", AB11*100, "% ")), IF(AC11=0, " ", CONCATENATE($N$8, ":", AC11*100, "% ")), " in this use case because ", AF11, " ", AG11, " ", AH11, " ", AI11, " ", AJ11, " has/have NA values in it") -> Readjusted weights: :57.1428571428572% :42.8571428571429% in this use case because has/have NA values in it | AF11: =IF(J11="NA", $J$8,"") | AG11: =IF(K11="NA", $J$8,"") | AH11: =IF(L11="NA", $J$8,"") | AI11: =IF(M11="NA", $J$8,"") | AJ11: =IF(N11="NA", $J$8,"") | AK11: {=SUMPRODUCT($C$10:$G$10,(C11:G11<>"NA")*1)} -> 1 | AL11: =IF(C11="NA",0,C$10/$AK11) -> 0.3 | AM11: =IF(D11="NA",0,D$10/$AK11) -> 0.4 | AN11: =IF(E11="NA",0,E$10/$AK11) -> 0.3 | AO11: =IF(F11="NA",0,F$10/$AK11) -> 0 | AP11: =IF(G11="NA",0,G$10/$AK11) -> 0 | AQ11: =IF(AK11<1, AR11, "") | AR11: =CONCATENATE("Readjusted weights: ", IF(AL11=0, " ", CONCATENATE($D$8, ":", AL11*100, "% ")), IF(AM11=0, " ", CONCATENATE($E$8, ":", AM11*100, "% ")), IF(AN11=0, " ", CONCATENATE($F$8, ":", AN11*100, "% ")), IF(AO11=0, " ", CONCATENATE($G$8, ":", AO11*100, "% ")), IF(AP11=0, " ", CONCATENATE($H$8, ":", AP11*100, "% ")), " in this use case because ", AS11, " ", AT11, " ", AU11, " ", AV11, " ", AW11, " has/have NA values in it") -> Readjusted weights: :30% :40% :30% in this use case because has/have NA values in it | AS11: =IF(C11="NA", C$10,"") | AT11: =IF(D11="NA", D$10,"") | AU11: =IF(E11="NA", E$10,"") | AV11: =IF(F11="NA", F$10,"") | AW11: =IF(G11="NA", G$10,"") | AX11: =SUMPRODUCT(C11:G11,AL11:AP11) -> 2.4 | AY11: =SUMPRODUCT(I11:M11,Y11:AC11) -> 1.5714286
A12: ='Step 1 - Fill in Details'!C8 -> Example Use Case 2 | B12: ='Step 1 - Fill in Details'!D8 -> TRUE | C12: 1 | D12: 0 | E12: 3 | I12: NA | J12: NA | K12: 1 | O12: =AX12 -> 1.2 | P12: =AY12 -> 1 | Q12: {=P12+O12+(RAND()*0.00000000000001+1/ROW(2:2)*0.000001)} -> 2.2000005 | R12: =AND(P12=0,O12=0) -> FALSE | S12: {=SUMPRODUCT(($R$11:R12)*1)} -> 0 | U12: =AND(O12=0,P12=0) -> FALSE | V12: {=SUMPRODUCT(($U$10:U12)*1)} -> 0 | X12: {=SUMPRODUCT($I$10:$M$10,(I12:M12<>"NA")*1)} -> 0.3 | Y12: =IF(I12="NA",0,I$10/$X12) -> 0 | Z12: =IF(J12="NA",0,J$10/$X12) -> 0 | AA12: =IF(K12="NA",0,K$10/$X12) -> 1 | AB12: =IF(L12="NA",0,L$10/$X12) -> 0 | AC12: =IF(M12="NA",0,M$10/$X12) -> 0 | AD12: =IF(X12<1, AE12, "") -> Readjusted weights: :100% in this use case because 0 has/have NA values in it | AE12: =CONCATENATE("Readjusted weights: ", IF(Y12=0, " ", CONCATENATE($J$8, ":", Y12*100, "% ")), IF(Z12=0, " ", CONCATENATE($K$8, ":", Z12*100, "% ")), IF(AA12=0, " ", CONCATENATE($L$8, ":", AA12*100, "% ")), IF(AB12=0, " ", CONCATENATE($M$8, ":", AB12*100, "% ")), IF(AC12=0, " ", CONCATENATE($N$8, ":", AC12*100, "% ")), " in this use case because ", AF12, " ", AG12, " ", AH12, " ", AI12, " ", AJ12, " has/have NA values in it") -> Readjusted weights: :100% in this use case because 0 has/have NA values in it | AF12: =IF(J12="NA", $J$8,"") -> 0 | AG12: =IF(K12="NA", $J$8,"") | AH12: =IF(L12="NA", $J$8,"") | AI12: =IF(M12="NA", $J$8,"") | AJ12: =IF(N12="NA", $J$8,"") | AK12: {=SUMPRODUCT($C$10:$G$10,(C12:G12<>"NA")*1)} -> 1 | AL12: =IF(C12="NA",0,C$10/$AK12) -> 0.3 | AM12: =IF(D12="NA",0,D$10/$AK12) -> 0.4 | AN12: =IF(E12="NA",0,E$10/$AK12) -> 0.3 | AO12: =IF(F12="NA",0,F$10/$AK12) -> 0 | AP12: =IF(G12="NA",0,G$10/$AK12) -> 0 | AQ12: =IF(AK12<1, AR12, "") | AR12: =CONCATENATE("Readjusted weights: ", IF(AL12=0, " ", CONCATENATE($D$8, ":", AL12*100, "% ")), IF(AM12=0, " ", CONCATENATE($E$8, ":", AM12*100, "% ")), IF(AN12=0, " ", CONCATENATE($F$8, ":", AN12*100, "% ")), IF(AO12=0, " ", CONCATENATE($G$8, ":", AO12*100, "% ")), IF(AP12=0, " ", CONCATENATE($H$8, ":", AP12*100, "% ")), " in this use case because ", AS12, " ", AT12, " ", AU12, " ", AV12, " ", AW12, " has/have NA values in it") -> Readjusted weights: :30% :40% :30% in this use case because has/have NA values in it | AS12: =IF(C12="NA", C$10,"") | AT12: =IF(D12="NA", D$10,"") | AU12: =IF(E12="NA", E$10,"") | AV12: =IF(F12="NA", F$10,"") | AW12: =IF(G12="NA", G$10,"") | AX12: =SUMPRODUCT(C12:G12,AL12:AP12) -> 1.2 | AY12: =SUMPRODUCT(I12:M12,Y12:AC12) -> 1
A13: ='Step 1 - Fill in Details'!C9 -> UC3 | B13: ='Step 1 - Fill in Details'!D9 -> FALSE | O13: =AX13 -> 0 | P13: =AY13 -> 0 | Q13: {=P13+O13+(RAND()*0.00000000000001+1/ROW(3:3)*0.000001)} -> 3.3333334e-07 | R13: =AND(P13=0,O13=0) -> TRUE | S13: {=SUMPRODUCT(($R$11:R13)*1)} -> 1 | U13: =AND(O13=0,P13=0) -> TRUE | V13: {=SUMPRODUCT(($U$10:U13)*1)} -> 1 | X13: {=SUMPRODUCT($I$10:$M$10,(I13:M13<>"NA")*1)} -> 1 | Y13: =IF(I13="NA",0,I$10/$X13) -> 0.3 | Z13: =IF(J13="NA",0,J$10/$X13) -> 0.4 | AA13: =IF(K13="NA",0,K$10/$X13) -> 0.3 | AB13: =IF(L13="NA",0,L$10/$X13) -> 0 | AC13: =IF(M13="NA",0,M$10/$X13) -> 0 | AD13: =IF(X13<1, AE13, "") | AE13: =CONCATENATE("Readjusted weights: ", IF(Y13=0, " ", CONCATENATE($J$8, ":", Y13*100, "% ")), IF(Z13=0, " ", CONCATENATE($K$8, ":", Z13*100, "% ")), IF(AA13=0, " ", CONCATENATE($L$8, ":", AA13*100, "% ")), IF(AB13=0, " ", CONCATENATE($M$8, ":", AB13*100, "% ")), IF(AC13=0, " ", CONCATENATE($N$8, ":", AC13*100, "% ")), " in this use case because ", AF13, " ", AG13, " ", AH13, " ", AI13, " ", AJ13, " has/have NA values in it") -> Readjusted weights: :30% :40% :30% in this use case because has/have NA values in it | AF13: =IF(J13="NA", $J$8,"") | AG13: =IF(K13="NA", $J$8,"") | AH13: =IF(L13="NA", $J$8,"") | AI13: =IF(M13="NA", $J$8,"") | AJ13: =IF(N13="NA", $J$8,"") | AK13: {=SUMPRODUCT($C$10:$G$10,(C13:G13<>"NA")*1)} -> 1 | AL13: =IF(C13="NA",0,C$10/$AK13) -> 0.3 | AM13: =IF(D13="NA",0,D$10/$AK13) -> 0.4 | AN13: =IF(E13="NA",0,E$10/$AK13) -> 0.3 | AO13: =IF(F13="NA",0,F$10/$AK13) -> 0 | AP13: =IF(G13="NA",0,G$10/$AK13) -> 0 | AQ13: =IF(AK13<1, AR13, "") | AR13: =CONCATENATE("Readjusted weights: ", IF(AL13=0, " ", CONCATENATE($D$8, ":", AL13*100, "% ")), IF(AM13=0, " ", CONCATENATE($E$8, ":", AM13*100, "% ")), IF(AN13=0, " ", CONCATENATE($F$8, ":", AN13*100, "% ")), IF(AO13=0, " ", CONCATENATE($G$8, ":", AO13*100, "% ")), IF(AP13=0, " ", CONCATENATE($H$8, ":", AP13*100, "% ")), " in this use case because ", AS13, " ", AT13, " ", AU13, " ", AV13, " ", AW13, " has/have NA values in it") -> Readjusted weights: :30% :40% :30% in this use case because has/have NA values in it | AS13: =IF(C13="NA", C$10,"") | AT13: =IF(D13="NA", D$10,"") | AU13: =IF(E13="NA", E$10,"") | AV13: =IF(F13="NA", F$10,"") | AW13: =IF(G13="NA", G$10,"") | AX13: =SUMPRODUCT(C13:G13,AL13:AP13) -> 0 | AY13: =SUMPRODUCT(I13:M13,Y13:AC13) -> 0
A14: ='Step 1 - Fill in Details'!C10 -> UC4 | B14: ='Step 1 - Fill in Details'!D10 -> FALSE | O14: =AX14 -> 0 | P14: =AY14 -> 0 | Q14: {=P14+O14+(RAND()*0.00000000000001+1/ROW(4:4)*0.000001)} -> 2.5000001e-07 | R14: =AND(P14=0,O14=0) -> TRUE | S14: {=SUMPRODUCT(($R$11:R14)*1)} -> 2 | U14: =AND(O14=0,P14=0) -> TRUE | V14: {=SUMPRODUCT(($U$10:U14)*1)} -> 2 | X14: {=SUMPRODUCT($I$10:$M$10,(I14:M14<>"NA")*1)} -> 1 | Y14: =IF(I14="NA",0,I$10/$X14) -> 0.3 | Z14: =IF(J14="NA",0,J$10/$X14) -> 0.4 | AA14: =IF(K14="NA",0,K$10/$X14) -> 0.3 | AB14: =IF(L14="NA",0,L$10/$X14) -> 0 | AC14: =IF(M14="NA",0,M$10/$X14) -> 0 | AD14: =IF(X14<1, AE14, "") | AE14: =CONCATENATE("Readjusted weights: ", IF(Y14=0, " ", CONCATENATE($J$8, ":", Y14*100, "% ")), IF(Z14=0, " ", CONCATENATE($K$8, ":", Z14*100, "% ")), IF(AA14=0, " ", CONCATENATE($L$8, ":", AA14*100, "% ")), IF(AB14=0, " ", CONCATENATE($M$8, ":", AB14*100, "% ")), IF(AC14=0, " ", CONCATENATE($N$8, ":", AC14*100, "% ")), " in this use case because ", AF14, " ", AG14, " ", AH14, " ", AI14, " ", AJ14, " has/have NA values in it") -> Readjusted weights: :30% :40% :30% in this use case because has/have NA values in it | AF14: =IF(J14="NA", $J$8,"") | AG14: =IF(K14="NA", $J$8,"") | AH14: =IF(L14="NA", $J$8,"") | AI14: =IF(M14="NA", $J$8,"") | AJ14: =IF(N14="NA", $J$8,"") | AK14: {=SUMPRODUCT($C$10:$G$10,(C14:G14<>"NA")*1)} -> 1 | AL14: =IF(C14="NA",0,C$10/$AK14) -> 0.3 | AM14: =IF(D14="NA",0,D$10/$AK14) -> 0.4 | AN14: =IF(E14="NA",0,E$10/$AK14) -> 0.3 | AO14: =IF(F14="NA",0,F$10/$AK14) -> 0 | AP14: =IF(G14="NA",0,G$10/$AK14) -> 0 | AQ14: =IF(AK14<1, AR14, "") | AR14: =CONCATENATE("Readjusted weights: ", IF(AL14=0, " ", CONCATENATE($D$8, ":", AL14*100, "% ")), IF(AM14=0, " ", CONCATENATE($E$8, ":", AM14*100, "% ")), IF(AN14=0, " ", CONCATENATE($F$8, ":", AN14*100, "% ")), IF(AO14=0, " ", CONCATENATE($G$8, ":", AO14*100, "% ")), IF(AP14=0, " ", CONCATENATE($H$8, ":", AP14*100, "% ")), " in this use case because ", AS14, " ", AT14, " ", AU14, " ", AV14, " ", AW14, " has/have NA values in it") -> Readjusted weights: :30% :40% :30% in this use case because has/have NA values in it | AS14: =IF(C14="NA", C$10,"") | AT14: =IF(D14="NA", D$10,"") | AU14: =IF(E14="NA", E$10,"") | AV14: =IF(F14="NA", F$10,"") | AW14: =IF(G14="NA", G$10,"") | AX14: =SUMPRODUCT(C14:G14,AL14:AP14) -> 0 | AY14: =SUMPRODUCT(I14:M14,Y14:AC14) -> 0
A15: ='Step 1 - Fill in Details'!C11 -> UC5 | B15: ='Step 1 - Fill in Details'!D11 -> FALSE | O15: =AX15 -> 0 | P15: =AY15 -> 0 | Q15: {=P15+O15+(RAND()*0.00000000000001+1/ROW(5:5)*0.000001)} -> 2.0000001e-07 | R15: =AND(P15=0,O15=0) -> TRUE | S15: {=SUMPRODUCT(($R$11:R15)*1)} -> 3 | U15: =AND(O15=0,P15=0) -> TRUE | V15: {=SUMPRODUCT(($U$10:U15)*1)} -> 3 | X15: {=SUMPRODUCT($I$10:$M$10,(I15:M15<>"NA")*1)} -> 1 | Y15: =IF(I15="NA",0,I$10/$X15) -> 0.3 | Z15: =IF(J15="NA",0,J$10/$X15) -> 0.4 | AA15: =IF(K15="NA",0,K$10/$X15) -> 0.3 | AB15: =IF(L15="NA",0,L$10/$X15) -> 0 | AC15: =IF(M15="NA",0,M$10/$X15) -> 0 | AD15: =IF(X15<1, AE15, "") | AE15: =CONCATENATE("Readjusted weights: ", IF(Y15=0, " ", CONCATENATE($J$8, ":", Y15*100, "% ")), IF(Z15=0, " ", CONCATENATE($K$8, ":", Z15*100, "% ")), IF(AA15=0, " ", CONCATENATE($L$8, ":", AA15*100, "% ")), IF(AB15=0, " ", CONCATENATE($M$8, ":", AB15*100, "% ")), IF(AC15=0, " ", CONCATENATE($N$8, ":", AC15*100, "% ")), " in this use case because ", AF15, " ", AG15, " ", AH15, " ", AI15, " ", AJ15, " has/have NA values in it") -> Readjusted weights: :30% :40% :30% in this use case because has/have NA values in it | AF15: =IF(J15="NA", $J$8,"") | AG15: =IF(K15="NA", $J$8,"") | AH15: =IF(L15="NA", $J$8,"") | AI15: =IF(M15="NA", $J$8,"") | AJ15: =IF(N15="NA", $J$8,"") | AK15: {=SUMPRODUCT($C$10:$G$10,(C15:G15<>"NA")*1)} -> 1 | AL15: =IF(C15="NA",0,C$10/$AK15) -> 0.3 | AM15: =IF(D15="NA",0,D$10/$AK15) -> 0.4 | AN15: =IF(E15="NA",0,E$10/$AK15) -> 0.3 | AO15: =IF(F15="NA",0,F$10/$AK15) -> 0 | AP15: =IF(G15="NA",0,G$10/$AK15) -> 0 | AQ15: =IF(AK15<1, AR15, "") | AR15: =CONCATENATE("Readjusted weights: ", IF(AL15=0, " ", CONCATENATE($D$8, ":", AL15*100, "% ")), IF(AM15=0, " ", CONCATENATE($E$8, ":", AM15*100, "% ")), IF(AN15=0, " ", CONCATENATE($F$8, ":", AN15*100, "% ")), IF(AO15=0, " ", CONCATENATE($G$8, ":", AO15*100, "% ")), IF(AP15=0, " ", CONCATENATE($H$8, ":", AP15*100, "% ")), " in this use case because ", AS15, " ", AT15, " ", AU15, " ", AV15, " ", AW15, " has/have NA values in it") -> Readjusted weights: :30% :40% :30% in this use case because has/have NA values in it | AS15: =IF(C15="NA", C$10,"") | AT15: =IF(D15="NA", D$10,"") | AU15: =IF(E15="NA", E$10,"") | AV15: =IF(F15="NA", F$10,"") | AW15: =IF(G15="NA", G$10,"") | AX15: =SUMPRODUCT(C15:G15,AL15:AP15) -> 0 | AY15: =SUMPRODUCT(I15:M15,Y15:AC15) -> 0
A16: ='Step 1 - Fill in Details'!C12 -> UC6 | B16: ='Step 1 - Fill in Details'!D12 -> FALSE | O16: =AX16 -> 0 | P16: =AY16 -> 0 | Q16: {=P16+O16+(RAND()*0.00000000000001+1/ROW(6:6)*0.000001)} -> 1.6666667e-07 | R16: =AND(P16=0,O16=0) -> TRUE | S16: {=SUMPRODUCT(($R$11:R16)*1)} -> 4 | U16: =AND(O16=0,P16=0) -> TRUE | V16: {=SUMPRODUCT(($U$10:U16)*1)} -> 4 | X16: {=SUMPRODUCT($I$10:$M$10,(I16:M16<>"NA")*1)} -> 1 | Y16: =IF(I16="NA",0,I$10/$X16) -> 0.3 | Z16: =IF(J16="NA",0,J$10/$X16) -> 0.4 | AA16: =IF(K16="NA",0,K$10/$X16) -> 0.3 | AB16: =IF(L16="NA",0,L$10/$X16) -> 0 | AC16: =IF(M16="NA",0,M$10/$X16) -> 0 | AD16: =IF(X16<1, AE16, "") | AE16: =CONCATENATE("Readjusted weights: ", IF(Y16=0, " ", CONCATENATE($J$8, ":", Y16*100, "% ")), IF(Z16=0, " ", CONCATENATE($K$8, ":", Z16*100, "% ")), IF(AA16=0, " ", CONCATENATE($L$8, ":", AA16*100, "% ")), IF(AB16=0, " ", CONCATENATE($M$8, ":", AB16*100, "% ")), IF(AC16=0, " ", CONCATENATE($N$8, ":", AC16*100, "% ")), " in this use case because ", AF16, " ", AG16, " ", AH16, " ", AI16, " ", AJ16, " has/have NA values in it") -> Readjusted weights: :30% :40% :30% in this use case because has/have NA values in it | AF16: =IF(J16="NA", $J$8,"") | AG16: =IF(K16="NA", $J$8,"") | AH16: =IF(L16="NA", $J$8,"") | AI16: =IF(M16="NA", $J$8,"") | AJ16: =IF(N16="NA", $J$8,"") | AK16: {=SUMPRODUCT($C$10:$G$10,(C16:G16<>"NA")*1)} -> 1 | AL16: =IF(C16="NA",0,C$10/$AK16) -> 0.3 | AM16: =IF(D16="NA",0,D$10/$AK16) -> 0.4 | AN16: =IF(E16="NA",0,E$10/$AK16) -> 0.3 | AO16: =IF(F16="NA",0,F$10/$AK16) -> 0 | AP16: =IF(G16="NA",0,G$10/$AK16) -> 0 | AQ16: =IF(AK16<1, AR16, "") | AR16: =CONCATENATE("Readjusted weights: ", IF(AL16=0, " ", CONCATENATE($D$8, ":", AL16*100, "% ")), IF(AM16=0, " ", CONCATENATE($E$8, ":", AM16*100, "% ")), IF(AN16=0, " ", CONCATENATE($F$8, ":", AN16*100, "% ")), IF(AO16=0, " ", CONCATENATE($G$8, ":", AO16*100, "% ")), IF(AP16=0, " ", CONCATENATE($H$8, ":", AP16*100, "% ")), " in this use case because ", AS16, " ", AT16, " ", AU16, " ", AV16, " ", AW16, " has/have NA values in it") -> Readjusted weights: :30% :40% :30% in this use case because has/have NA values in it | AS16: =IF(C16="NA", C$10,"") | AT16: =IF(D16="NA", D$10,"") | AU16: =IF(E16="NA", E$10,"") | AV16: =IF(F16="NA", F$10,"") | AW16: =IF(G16="NA", G$10,"") | AX16: =SUMPRODUCT(C16:G16,AL16:AP16) -> 0 | AY16: =SUMPRODUCT(I16:M16,Y16:AC16) -> 0
A17: ='Step 1 - Fill in Details'!C13 -> UC7 | B17: ='Step 1 - Fill in Details'!D13 -> FALSE | O17: =AX17 -> 0 | P17: =AY17 -> 0 | Q17: {=P17+O17+(RAND()*0.00000000000001+1/ROW(7:7)*0.000001)} -> 1.4285714e-07 | R17: =AND(P17=0,O17=0) -> TRUE | S17: {=SUMPRODUCT(($R$11:R17)*1)} -> 5 | U17: =AND(O17=0,P17=0) -> TRUE | V17: {=SUMPRODUCT(($U$10:U17)*1)} -> 5 | X17: {=SUMPRODUCT($I$10:$M$10,(I17:M17<>"NA")*1)} -> 1 | Y17: =IF(I17="NA",0,I$10/$X17) -> 0.3 | Z17: =IF(J17="NA",0,J$10/$X17) -> 0.4 | AA17: =IF(K17="NA",0,K$10/$X17) -> 0.3 | AB17: =IF(L17="NA",0,L$10/$X17) -> 0 | AC17: =IF(M17="NA",0,M$10/$X17) -> 0 | AD17: =IF(X17<1, AE17, "") | AE17: =CONCATENATE("Readjusted weights: ", IF(Y17=0, " ", CONCATENATE($J$8, ":", Y17*100, "% ")), IF(Z17=0, " ", CONCATENATE($K$8, ":", Z17*100, "% ")), IF(AA17=0, " ", CONCATENATE($L$8, ":", AA17*100, "% ")), IF(AB17=0, " ", CONCATENATE($M$8, ":", AB17*100, "% ")), IF(AC17=0, " ", CONCATENATE($N$8, ":", AC17*100, "% ")), " in this use case because ", AF17, " ", AG17, " ", AH17, " ", AI17, " ", AJ17, " has/have NA values in it") -> Readjusted weights: :30% :40% :30% in this use case because has/have NA values in it | AF17: =IF(J17="NA", $J$8,"") | AG17: =IF(K17="NA", $J$8,"") | AH17: =IF(L17="NA", $J$8,"") | AI17: =IF(M17="NA", $J$8,"") | AJ17: =IF(N17="NA", $J$8,"") | AK17: {=SUMPRODUCT($C$10:$G$10,(C17:G17<>"NA")*1)} -> 1 | AL17: =IF(C17="NA",0,C$10/$AK17) -> 0.3 | AM17: =IF(D17="NA",0,D$10/$AK17) -> 0.4 | AN17: =IF(E17="NA",0,E$10/$AK17) -> 0.3 | AO17: =IF(F17="NA",0,F$10/$AK17) -> 0 | AP17: =IF(G17="NA",0,G$10/$AK17) -> 0 | AQ17: =IF(AK17<1, AR17, "") | AR17: =CONCATENATE("Readjusted weights: ", IF(AL17=0, " ", CONCATENATE($D$8, ":", AL17*100, "% ")), IF(AM17=0, " ", CONCATENATE($E$8, ":", AM17*100, "% ")), IF(AN17=0, " ", CONCATENATE($F$8, ":", AN17*100, "% ")), IF(AO17=0, " ", CONCATENATE($G$8, ":", AO17*100, "% ")), IF(AP17=0, " ", CONCATENATE($H$8, ":", AP17*100, "% ")), " in this use case because ", AS17, " ", AT17, " ", AU17, " ", AV17, " ", AW17, " has/have NA values in it") -> Readjusted weights: :30% :40% :30% in this use case because has/have NA values in it | AS17: =IF(C17="NA", C$10,"") | AT17: =IF(D17="NA", D$10,"") | AU17: =IF(E17="NA", E$10,"") | AV17: =IF(F17="NA", F$10,"") | AW17: =IF(G17="NA", G$10,"") | AX17: =SUMPRODUCT(C17:G17,AL17:AP17) -> 0 | AY17: =SUMPRODUCT(I17:M17,Y17:AC17) -> 0
A18: ='Step 1 - Fill in Details'!C14 -> UC8 | B18: ='Step 1 - Fill in Details'!D14 -> FALSE | O18: =AX18 -> 0 | P18: =AY18 -> 0 | Q18: {=P18+O18+(RAND()*0.00000000000001+1/ROW(8:8)*0.000001)} -> 1.2500001e-07 | R18: =AND(P18=0,O18=0) -> TRUE | S18: {=SUMPRODUCT(($R$11:R18)*1)} -> 6 | U18: =AND(O18=0,P18=0) -> TRUE | V18: {=SUMPRODUCT(($U$10:U18)*1)} -> 6 | X18: {=SUMPRODUCT($I$10:$M$10,(I18:M18<>"NA")*1)} -> 1 | Y18: =IF(I18="NA",0,I$10/$X18) -> 0.3 | Z18: =IF(J18="NA",0,J$10/$X18) -> 0.4 | AA18: =IF(K18="NA",0,K$10/$X18) -> 0.3 | AB18: =IF(L18="NA",0,L$10/$X18) -> 0 | AC18: =IF(M18="NA",0,M$10/$X18) -> 0 | AD18: =IF(X18<1, AE18, "") | AE18: =CONCATENATE("Readjusted weights: ", IF(Y18=0, " ", CONCATENATE($J$8, ":", Y18*100, "% ")), IF(Z18=0, " ", CONCATENATE($K$8, ":", Z18*100, "% ")), IF(AA18=0, " ", CONCATENATE($L$8, ":", AA18*100, "% ")), IF(AB18=0, " ", CONCATENATE($M$8, ":", AB18*100, "% ")), IF(AC18=0, " ", CONCATENATE($N$8, ":", AC18*100, "% ")), " in this use case because ", AF18, " ", AG18, " ", AH18, " ", AI18, " ", AJ18, " has/have NA values in it") -> Readjusted weights: :30% :40% :30% in this use case because has/have NA values in it | AF18: =IF(J18="NA", $J$8,"") | AG18: =IF(K18="NA", $J$8,"") | AH18: =IF(L18="NA", $J$8,"") | AI18: =IF(M18="NA", $J$8,"") | AJ18: =IF(N18="NA", $J$8,"") | AK18: {=SUMPRODUCT($C$10:$G$10,(C18:G18<>"NA")*1)} -> 1 | AL18: =IF(C18="NA",0,C$10/$AK18) -> 0.3 | AM18: =IF(D18="NA",0,D$10/$AK18) -> 0.4 | AN18: =IF(E18="NA",0,E$10/$AK18) -> 0.3 | AO18: =IF(F18="NA",0,F$10/$AK18) -> 0 | AP18: =IF(G18="NA",0,G$10/$AK18) -> 0 | AQ18: =IF(AK18<1, AR18, "") | AR18: =CONCATENATE("Readjusted weights: ", IF(AL18=0, " ", CONCATENATE($D$8, ":", AL18*100, "% ")), IF(AM18=0, " ", CONCATENATE($E$8, ":", AM18*100, "% ")), IF(AN18=0, " ", CONCATENATE($F$8, ":", AN18*100, "% ")), IF(AO18=0, " ", CONCATENATE($G$8, ":", AO18*100, "% ")), IF(AP18=0, " ", CONCATENATE($H$8, ":", AP18*100, "% ")), " in this use case because ", AS18, " ", AT18, " ", AU18, " ", AV18, " ", AW18, " has/have NA values in it") -> Readjusted weights: :30% :40% :30% in this use case because has/have NA values in it | AS18: =IF(C18="NA", C$10,"") | AT18: =IF(D18="NA", D$10,"") | AU18: =IF(E18="NA", E$10,"") | AV18: =IF(F18="NA", F$10,"") | AW18: =IF(G18="NA", G$10,"") | AX18: =SUMPRODUCT(C18:G18,AL18:AP18) -> 0 | AY18: =SUMPRODUCT(I18:M18,Y18:AC18) -> 0
A19: ='Step 1 - Fill in Details'!C15 -> UC9 | B19: ='Step 1 - Fill in Details'!D15 -> FALSE | O19: =AX19 -> 0 | P19: =AY19 -> 0 | Q19: {=P19+O19+(RAND()*0.00000000000001+1/ROW(9:9)*0.000001)} -> 1.1111111e-07 | R19: =AND(P19=0,O19=0) -> TRUE | S19: {=SUMPRODUCT(($R$11:R19)*1)} -> 7 | U19: =AND(O19=0,P19=0) -> TRUE | V19: {=SUMPRODUCT(($U$10:U19)*1)} -> 7 | X19: {=SUMPRODUCT($I$10:$M$10,(I19:M19<>"NA")*1)} -> 1 | Y19: =IF(I19="NA",0,I$10/$X19) -> 0.3 | Z19: =IF(J19="NA",0,J$10/$X19) -> 0.4 | AA19: =IF(K19="NA",0,K$10/$X19) -> 0.3 | AB19: =IF(L19="NA",0,L$10/$X19) -> 0 | AC19: =IF(M19="NA",0,M$10/$X19) -> 0 | AD19: =IF(X19<1, AE19, "") | AE19: =CONCATENATE("Readjusted weights: ", IF(Y19=0, " ", CONCATENATE($J$8, ":", Y19*100, "% ")), IF(Z19=0, " ", CONCATENATE($K$8, ":", Z19*100, "% ")), IF(AA19=0, " ", CONCATENATE($L$8, ":", AA19*100, "% ")), IF(AB19=0, " ", CONCATENATE($M$8, ":", AB19*100, "% ")), IF(AC19=0, " ", CONCATENATE($N$8, ":", AC19*100, "% ")), " in this use case because ", AF19, " ", AG19, " ", AH19, " ", AI19, " ", AJ19, " has/have NA values in it") -> Readjusted weights: :30% :40% :30% in this use case because has/have NA values in it | AF19: =IF(J19="NA", $J$8,"") | AG19: =IF(K19="NA", $J$8,"") | AH19: =IF(L19="NA", $J$8,"") | AI19: =IF(M19="NA", $J$8,"") | AJ19: =IF(N19="NA", $J$8,"") | AK19: {=SUMPRODUCT($C$10:$G$10,(C19:G19<>"NA")*1)} -> 1 | AL19: =IF(C19="NA",0,C$10/$AK19) -> 0.3 | AM19: =IF(D19="NA",0,D$10/$AK19) -> 0.4 | AN19: =IF(E19="NA",0,E$10/$AK19) -> 0.3 | AO19: =IF(F19="NA",0,F$10/$AK19) -> 0 | AP19: =IF(G19="NA",0,G$10/$AK19) -> 0 | AQ19: =IF(AK19<1, AR19, "") | AR19: =CONCATENATE("Readjusted weights: ", IF(AL19=0, " ", CONCATENATE($D$8, ":", AL19*100, "% ")), IF(AM19=0, " ", CONCATENATE($E$8, ":", AM19*100, "% ")), IF(AN19=0, " ", CONCATENATE($F$8, ":", AN19*100, "% ")), IF(AO19=0, " ", CONCATENATE($G$8, ":", AO19*100, "% ")), IF(AP19=0, " ", CONCATENATE($H$8, ":", AP19*100, "% ")), " in this use case because ", AS19, " ", AT19, " ", AU19, " ", AV19, " ", AW19, " has/have NA values in it") -> Readjusted weights: :30% :40% :30% in this use case because has/have NA values in it | AS19: =IF(C19="NA", C$10,"") | AT19: =IF(D19="NA", D$10,"") | AU19: =IF(E19="NA", E$10,"") | AV19: =IF(F19="NA", F$10,"") | AW19: =IF(G19="NA", G$10,"") | AX19: =SUMPRODUCT(C19:G19,AL19:AP19) -> 0 | AY19: =SUMPRODUCT(I19:M19,Y19:AC19) -> 0
A20: ='Step 1 - Fill in Details'!C16 -> UC10 | B20: ='Step 1 - Fill in Details'!D16 -> FALSE | O20: =AX20 -> 0 | P20: =AY20 -> 0 | Q20: {=P20+O20+(RAND()*0.00000000000001+1/ROW(10:10)*0.000001)} -> 1e-07 | R20: =AND(P20=0,O20=0) -> TRUE | S20: {=SUMPRODUCT(($R$11:R20)*1)} -> 8 | U20: =AND(O20=0,P20=0) -> TRUE | V20: {=SUMPRODUCT(($U$10:U20)*1)} -> 8 | X20: {=SUMPRODUCT($I$10:$M$10,(I20:M20<>"NA")*1)} -> 1 | Y20: =IF(I20="NA",0,I$10/$X20) -> 0.3 | Z20: =IF(J20="NA",0,J$10/$X20) -> 0.4 | AA20: =IF(K20="NA",0,K$10/$X20) -> 0.3 | AB20: =IF(L20="NA",0,L$10/$X20) -> 0 | AC20: =IF(M20="NA",0,M$10/$X20) -> 0 | AD20: =IF(X20<1, AE20, "") | AE20: =CONCATENATE("Readjusted weights: ", IF(Y20=0, " ", CONCATENATE($J$8, ":", Y20*100, "% ")), IF(Z20=0, " ", CONCATENATE($K$8, ":", Z20*100, "% ")), IF(AA20=0, " ", CONCATENATE($L$8, ":", AA20*100, "% ")), IF(AB20=0, " ", CONCATENATE($M$8, ":", AB20*100, "% ")), IF(AC20=0, " ", CONCATENATE($N$8, ":", AC20*100, "% ")), " in this use case because ", AF20, " ", AG20, " ", AH20, " ", AI20, " ", AJ20, " has/have NA values in it") -> Readjusted weights: :30% :40% :30% in this use case because has/have NA values in it | AF20: =IF(J20="NA", $J$8,"") | AG20: =IF(K20="NA", $J$8,"") | AH20: =IF(L20="NA", $J$8,"") | AI20: =IF(M20="NA", $J$8,"") | AJ20: =IF(N20="NA", $J$8,"") | AK20: {=SUMPRODUCT($C$10:$G$10,(C20:G20<>"NA")*1)} -> 1 | AL20: =IF(C20="NA",0,C$10/$AK20) -> 0.3 | AM20: =IF(D20="NA",0,D$10/$AK20) -> 0.4 | AN20: =IF(E20="NA",0,E$10/$AK20) -> 0.3 | AO20: =IF(F20="NA",0,F$10/$AK20) -> 0 | AP20: =IF(G20="NA",0,G$10/$AK20) -> 0 | AQ20: =IF(AK20<1, AR20, "") | AR20: =CONCATENATE("Readjusted weights: ", IF(AL20=0, " ", CONCATENATE($D$8, ":", AL20*100, "% ")), IF(AM20=0, " ", CONCATENATE($E$8, ":", AM20*100, "% ")), IF(AN20=0, " ", CONCATENATE($F$8, ":", AN20*100, "% ")), IF(AO20=0, " ", CONCATENATE($G$8, ":", AO20*100, "% ")), IF(AP20=0, " ", CONCATENATE($H$8, ":", AP20*100, "% ")), " in this use case because ", AS20, " ", AT20, " ", AU20, " ", AV20, " ", AW20, " has/have NA values in it") -> Readjusted weights: :30% :40% :30% in this use case because has/have NA values in it | AS20: =IF(C20="NA", C$10,"") | AT20: =IF(D20="NA", D$10,"") | AU20: =IF(E20="NA", E$10,"") | AV20: =IF(F20="NA", F$10,"") | AW20: =IF(G20="NA", G$10,"") | AX20: =SUMPRODUCT(C20:G20,AL20:AP20) -> 0 | AY20: =SUMPRODUCT(I20:M20,Y20:AC20) -> 0
A21: ='Step 1 - Fill in Details'!C17 -> UC11 | B21: ='Step 1 - Fill in Details'!D17 -> FALSE | O21: =AX21 -> 0 | P21: =AY21 -> 0 | Q21: {=P21+O21+(RAND()*0.00000000000001+1/ROW(11:11)*0.000001)} -> 9.0909094e-08 | R21: =AND(P21=0,O21=0) -> TRUE | S21: {=SUMPRODUCT(($R$11:R21)*1)} -> 9 | U21: =AND(O21=0,P21=0) -> TRUE | V21: {=SUMPRODUCT(($U$10:U21)*1)} -> 9 | X21: {=SUMPRODUCT($I$10:$M$10,(I21:M21<>"NA")*1)} -> 1 | Y21: =IF(I21="NA",0,I$10/$X21) -> 0.3 | Z21: =IF(J21="NA",0,J$10/$X21) -> 0.4 | AA21: =IF(K21="NA",0,K$10/$X21) -> 0.3 | AB21: =IF(L21="NA",0,L$10/$X21) -> 0 | AC21: =IF(M21="NA",0,M$10/$X21) -> 0 | AD21: =IF(X21<1, AE21, "") | AE21: =CONCATENATE("Readjusted weights: ", IF(Y21=0, " ", CONCATENATE($J$8, ":", Y21*100, "% ")), IF(Z21=0, " ", CONCATENATE($K$8, ":", Z21*100, "% ")), IF(AA21=0, " ", CONCATENATE($L$8, ":", AA21*100, "% ")), IF(AB21=0, " ", CONCATENATE($M$8, ":", AB21*100, "% ")), IF(AC21=0, " ", CONCATENATE($N$8, ":", AC21*100, "% ")), " in this use case because ", AF21, " ", AG21, " ", AH21, " ", AI21, " ", AJ21, " has/have NA values in it") -> Readjusted weights: :30% :40% :30% in this use case because has/have NA values in it | AF21: =IF(J21="NA", $J$8,"") | AG21: =IF(K21="NA", $J$8,"") | AH21: =IF(L21="NA", $J$8,"") | AI21: =IF(M21="NA", $J$8,"") | AJ21: =IF(N21="NA", $J$8,"") | AK21: {=SUMPRODUCT($C$10:$G$10,(C21:G21<>"NA")*1)} -> 1 | AL21: =IF(C21="NA",0,C$10/$AK21) -> 0.3 | AM21: =IF(D21="NA",0,D$10/$AK21) -> 0.4 | AN21: =IF(E21="NA",0,E$10/$AK21) -> 0.3 | AO21: =IF(F21="NA",0,F$10/$AK21) -> 0 | AP21: =IF(G21="NA",0,G$10/$AK21) -> 0 | AQ21: =IF(AK21<1, AR21, "") | AR21: =CONCATENATE("Readjusted weights: ", IF(AL21=0, " ", CONCATENATE($D$8, ":", AL21*100, "% ")), IF(AM21=0, " ", CONCATENATE($E$8, ":", AM21*100, "% ")), IF(AN21=0, " ", CONCATENATE($F$8, ":", AN21*100, "% ")), IF(AO21=0, " ", CONCATENATE($G$8, ":", AO21*100, "% ")), IF(AP21=0, " ", CONCATENATE($H$8, ":", AP21*100, "% ")), " in this use case because ", AS21, " ", AT21, " ", AU21, " ", AV21, " ", AW21, " has/have NA values in it") -> Readjusted weights: :30% :40% :30% in this use case because has/have NA values in it | AS21: =IF(C21="NA", C$10,"") | AT21: =IF(D21="NA", D$10,"") | AU21: =IF(E21="NA", E$10,"") | AV21: =IF(F21="NA", F$10,"") | AW21: =IF(G21="NA", G$10,"") | AX21: =SUMPRODUCT(C21:G21,AL21:AP21) -> 0 | AY21: =SUMPRODUCT(I21:M21,Y21:AC21) -> 0
A22: ='Step 1 - Fill in Details'!C18 -> UC12 | B22: ='Step 1 - Fill in Details'!D18 -> FALSE | O22: =AX22 -> 0 | P22: =AY22 -> 0 | Q22: {=P22+O22+(RAND()*0.00000000000001+1/ROW(12:12)*0.000001)} -> 8.3333335e-08 | R22: =AND(P22=0,O22=0) -> TRUE | S22: {=SUMPRODUCT(($R$11:R22)*1)} -> 10 | U22: =AND(O22=0,P22=0) -> TRUE | V22: {=SUMPRODUCT(($U$10:U22)*1)} -> 10 | X22: {=SUMPRODUCT($I$10:$M$10,(I22:M22<>"NA")*1)} -> 1 | Y22: =IF(I22="NA",0,I$10/$X22) -> 0.3 | Z22: =IF(J22="NA",0,J$10/$X22) -> 0.4 | AA22: =IF(K22="NA",0,K$10/$X22) -> 0.3 | AB22: =IF(L22="NA",0,L$10/$X22) -> 0 | AC22: =IF(M22="NA",0,M$10/$X22) -> 0 | AD22: =IF(X22<1, AE22, "") | AE22: =CONCATENATE("Readjusted weights: ", IF(Y22=0, " ", CONCATENATE($J$8, ":", Y22*100, "% ")), IF(Z22=0, " ", CONCATENATE($K$8, ":", Z22*100, "% ")), IF(AA22=0, " ", CONCATENATE($L$8, ":", AA22*100, "% ")), IF(AB22=0, " ", CONCATENATE($M$8, ":", AB22*100, "% ")), IF(AC22=0, " ", CONCATENATE($N$8, ":", AC22*100, "% ")), " in this use case because ", AF22, " ", AG22, " ", AH22, " ", AI22, " ", AJ22, " has/have NA values in it") -> Readjusted weights: :30% :40% :30% in this use case because has/have NA values in it | AF22: =IF(J22="NA", $J$8,"") | AG22: =IF(K22="NA", $J$8,"") | AH22: =IF(L22="NA", $J$8,"") | AI22: =IF(M22="NA", $J$8,"") | AJ22: =IF(N22="NA", $J$8,"") | AK22: {=SUMPRODUCT($C$10:$G$10,(C22:G22<>"NA")*1)} -> 1 | AL22: =IF(C22="NA",0,C$10/$AK22) -> 0.3 | AM22: =IF(D22="NA",0,D$10/$AK22) -> 0.4 | AN22: =IF(E22="NA",0,E$10/$AK22) -> 0.3 | AO22: =IF(F22="NA",0,F$10/$AK22) -> 0 | AP22: =IF(G22="NA",0,G$10/$AK22) -> 0 | AQ22: =IF(AK22<1, AR22, "") | AR22: =CONCATENATE("Readjusted weights: ", IF(AL22=0, " ", CONCATENATE($D$8, ":", AL22*100, "% ")), IF(AM22=0, " ", CONCATENATE($E$8, ":", AM22*100, "% ")), IF(AN22=0, " ", CONCATENATE($F$8, ":", AN22*100, "% ")), IF(AO22=0, " ", CONCATENATE($G$8, ":", AO22*100, "% ")), IF(AP22=0, " ", CONCATENATE($H$8, ":", AP22*100, "% ")), " in this use case because ", AS22, " ", AT22, " ", AU22, " ", AV22, " ", AW22, " has/have NA values in it") -> Readjusted weights: :30% :40% :30% in this use case because has/have NA values in it | AS22: =IF(C22="NA", C$10,"") | AT22: =IF(D22="NA", D$10,"") | AU22: =IF(E22="NA", E$10,"") | AV22: =IF(F22="NA", F$10,"") | AW22: =IF(G22="NA", G$10,"") | AX22: =SUMPRODUCT(C22:G22,AL22:AP22) -> 0 | AY22: =SUMPRODUCT(I22:M22,Y22:AC22) -> 0
A23: ='Step 1 - Fill in Details'!C19 -> UC13 | B23: ='Step 1 - Fill in Details'!D19 -> FALSE | O23: =AX23 -> 0 | P23: =AY23 -> 0 | Q23: {=P23+O23+(RAND()*0.00000000000001+1/ROW(13:13)*0.000001)} -> 7.6923084e-08 | R23: =AND(P23=0,O23=0) -> TRUE | S23: {=SUMPRODUCT(($R$11:R23)*1)} -> 11 | U23: =AND(O23=0,P23=0) -> TRUE | V23: {=SUMPRODUCT(($U$10:U23)*1)} -> 11 | X23: {=SUMPRODUCT($I$10:$M$10,(I23:M23<>"NA")*1)} -> 1 | Y23: =IF(I23="NA",0,I$10/$X23) -> 0.3 | Z23: =IF(J23="NA",0,J$10/$X23) -> 0.4 | AA23: =IF(K23="NA",0,K$10/$X23) -> 0.3 | AB23: =IF(L23="NA",0,L$10/$X23) -> 0 | AC23: =IF(M23="NA",0,M$10/$X23) -> 0 | AD23: =IF(X23<1, AE23, "") | AE23: =CONCATENATE("Readjusted weights: ", IF(Y23=0, " ", CONCATENATE($J$8, ":", Y23*100, "% ")), IF(Z23=0, " ", CONCATENATE($K$8, ":", Z23*100, "% ")), IF(AA23=0, " ", CONCATENATE($L$8, ":", AA23*100, "% ")), IF(AB23=0, " ", CONCATENATE($M$8, ":", AB23*100, "% ")), IF(AC23=0, " ", CONCATENATE($N$8, ":", AC23*100, "% ")), " in this use case because ", AF23, " ", AG23, " ", AH23, " ", AI23, " ", AJ23, " has/have NA values in it") -> Readjusted weights: :30% :40% :30% in this use case because has/have NA values in it | AF23: =IF(J23="NA", $J$8,"") | AG23: =IF(K23="NA", $J$8,"") | AH23: =IF(L23="NA", $J$8,"") | AI23: =IF(M23="NA", $J$8,"") | AJ23: =IF(N23="NA", $J$8,"") | AK23: {=SUMPRODUCT($C$10:$G$10,(C23:G23<>"NA")*1)} -> 1 | AL23: =IF(C23="NA",0,C$10/$AK23) -> 0.3 | AM23: =IF(D23="NA",0,D$10/$AK23) -> 0.4 | AN23: =IF(E23="NA",0,E$10/$AK23) -> 0.3 | AO23: =IF(F23="NA",0,F$10/$AK23) -> 0 | AP23: =IF(G23="NA",0,G$10/$AK23) -> 0 | AQ23: =IF(AK23<1, AR23, "") | AR23: =CONCATENATE("Readjusted weights: ", IF(AL23=0, " ", CONCATENATE($D$8, ":", AL23*100, "% ")), IF(AM23=0, " ", CONCATENATE($E$8, ":", AM23*100, "% ")), IF(AN23=0, " ", CONCATENATE($F$8, ":", AN23*100, "% ")), IF(AO23=0, " ", CONCATENATE($G$8, ":", AO23*100, "% ")), IF(AP23=0, " ", CONCATENATE($H$8, ":", AP23*100, "% ")), " in this use case because ", AS23, " ", AT23, " ", AU23, " ", AV23, " ", AW23, " has/have NA values in it") -> Readjusted weights: :30% :40% :30% in this use case because has/have NA values in it | AS23: =IF(C23="NA", C$10,"") | AT23: =IF(D23="NA", D$10,"") | AU23: =IF(E23="NA", E$10,"") | AV23: =IF(F23="NA", F$10,"") | AW23: =IF(G23="NA", G$10,"") | AX23: =SUMPRODUCT(C23:G23,AL23:AP23) -> 0 | AY23: =SUMPRODUCT(I23:M23,Y23:AC23) -> 0
A24: ='Step 1 - Fill in Details'!C20 -> UC14 | B24: ='Step 1 - Fill in Details'!D20 -> FALSE | O24: =AX24 -> 0 | P24: =AY24 -> 0 | Q24: {=P24+O24+(RAND()*0.00000000000001+1/ROW(14:14)*0.000001)} -> 7.1428572e-08 | R24: =AND(P24=0,O24=0) -> TRUE | S24: {=SUMPRODUCT(($R$11:R24)*1)} -> 12 | U24: =AND(O24=0,P24=0) -> TRUE | V24: {=SUMPRODUCT(($U$10:U24)*1)} -> 12 | X24: {=SUMPRODUCT($I$10:$M$10,(I24:M24<>"NA")*1)} -> 1 | Y24: =IF(I24="NA",0,I$10/$X24) -> 0.3 | Z24: =IF(J24="NA",0,J$10/$X24) -> 0.4 | AA24: =IF(K24="NA",0,K$10/$X24) -> 0.3 | AB24: =IF(L24="NA",0,L$10/$X24) -> 0 | AC24: =IF(M24="NA",0,M$10/$X24) -> 0 | AD24: =IF(X24<1, AE24, "") | AE24: =CONCATENATE("Readjusted weights: ", IF(Y24=0, " ", CONCATENATE($J$8, ":", Y24*100, "% ")), IF(Z24=0, " ", CONCATENATE($K$8, ":", Z24*100, "% ")), IF(AA24=0, " ", CONCATENATE($L$8, ":", AA24*100, "% ")), IF(AB24=0, " ", CONCATENATE($M$8, ":", AB24*100, "% ")), IF(AC24=0, " ", CONCATENATE($N$8, ":", AC24*100, "% ")), " in this use case because ", AF24, " ", AG24, " ", AH24, " ", AI24, " ", AJ24, " has/have NA values in it") -> Readjusted weights: :30% :40% :30% in this use case because has/have NA values in it | AF24: =IF(J24="NA", $J$8,"") | AG24: =IF(K24="NA", $J$8,"") | AH24: =IF(L24="NA", $J$8,"") | AI24: =IF(M24="NA", $J$8,"") | AJ24: =IF(N24="NA", $J$8,"") | AK24: {=SUMPRODUCT($C$10:$G$10,(C24:G24<>"NA")*1)} -> 1 | AL24: =IF(C24="NA",0,C$10/$AK24) -> 0.3 | AM24: =IF(D24="NA",0,D$10/$AK24) -> 0.4 | AN24: =IF(E24="NA",0,E$10/$AK24) -> 0.3 | AO24: =IF(F24="NA",0,F$10/$AK24) -> 0 | AP24: =IF(G24="NA",0,G$10/$AK24) -> 0 | AQ24: =IF(AK24<1, AR24, "") | AR24: =CONCATENATE("Readjusted weights: ", IF(AL24=0, " ", CONCATENATE($D$8, ":", AL24*100, "% ")), IF(AM24=0, " ", CONCATENATE($E$8, ":", AM24*100, "% ")), IF(AN24=0, " ", CONCATENATE($F$8, ":", AN24*100, "% ")), IF(AO24=0, " ", CONCATENATE($G$8, ":", AO24*100, "% ")), IF(AP24=0, " ", CONCATENATE($H$8, ":", AP24*100, "% ")), " in this use case because ", AS24, " ", AT24, " ", AU24, " ", AV24, " ", AW24, " has/have NA values in it") -> Readjusted weights: :30% :40% :30% in this use case because has/have NA values in it | AS24: =IF(C24="NA", C$10,"") | AT24: =IF(D24="NA", D$10,"") | AU24: =IF(E24="NA", E$10,"") | AV24: =IF(F24="NA", F$10,"") | AW24: =IF(G24="NA", G$10,"") | AX24: =SUMPRODUCT(C24:G24,AL24:AP24) -> 0 | AY24: =SUMPRODUCT(I24:M24,Y24:AC24) -> 0
A25: ='Step 1 - Fill in Details'!C21 -> UC15 | B25: ='Step 1 - Fill in Details'!D21 -> FALSE | O25: =AX25 -> 0 | P25: =AY25 -> 0 | Q25: {=P25+O25+(RAND()*0.00000000000001+1/ROW(15:15)*0.000001)} -> 6.6666674e-08 | R25: =AND(P25=0,O25=0) -> TRUE | S25: {=SUMPRODUCT(($R$11:R25)*1)} -> 13 | U25: =AND(O25=0,P25=0) -> TRUE | V25: {=SUMPRODUCT(($U$10:U25)*1)} -> 13 | X25: {=SUMPRODUCT($I$10:$M$10,(I25:M25<>"NA")*1)} -> 1 | Y25: =IF(I25="NA",0,I$10/$X25) -> 0.3 | Z25: =IF(J25="NA",0,J$10/$X25) -> 0.4 | AA25: =IF(K25="NA",0,K$10/$X25) -> 0.3 | AB25: =IF(L25="NA",0,L$10/$X25) -> 0 | AC25: =IF(M25="NA",0,M$10/$X25) -> 0 | AD25: =IF(X25<1, AE25, "") | AE25: =CONCATENATE("Readjusted weights: ", IF(Y25=0, " ", CONCATENATE($J$8, ":", Y25*100, "% ")), IF(Z25=0, " ", CONCATENATE($K$8, ":", Z25*100, "% ")), IF(AA25=0, " ", CONCATENATE($L$8, ":", AA25*100, "% ")), IF(AB25=0, " ", CONCATENATE($M$8, ":", AB25*100, "% ")), IF(AC25=0, " ", CONCATENATE($N$8, ":", AC25*100, "% ")), " in this use case because ", AF25, " ", AG25, " ", AH25, " ", AI25, " ", AJ25, " has/have NA values in it") -> Readjusted weights: :30% :40% :30% in this use case because has/have NA values in it | AF25: =IF(J25="NA", $J$8,"") | AG25: =IF(K25="NA", $J$8,"") | AH25: =IF(L25="NA", $J$8,"") | AI25: =IF(M25="NA", $J$8,"") | AJ25: =IF(N25="NA", $J$8,"") | AK25: {=SUMPRODUCT($C$10:$G$10,(C25:G25<>"NA")*1)} -> 1 | AL25: =IF(C25="NA",0,C$10/$AK25) -> 0.3 | AM25: =IF(D25="NA",0,D$10/$AK25) -> 0.4 | AN25: =IF(E25="NA",0,E$10/$AK25) -> 0.3 | AO25: =IF(F25="NA",0,F$10/$AK25) -> 0 | AP25: =IF(G25="NA",0,G$10/$AK25) -> 0 | AQ25: =IF(AK25<1, AR25, "") | AR25: =CONCATENATE("Readjusted weights: ", IF(AL25=0, " ", CONCATENATE($D$8, ":", AL25*100, "% ")), IF(AM25=0, " ", CONCATENATE($E$8, ":", AM25*100, "% ")), IF(AN25=0, " ", CONCATENATE($F$8, ":", AN25*100, "% ")), IF(AO25=0, " ", CONCATENATE($G$8, ":", AO25*100, "% ")), IF(AP25=0, " ", CONCATENATE($H$8, ":", AP25*100, "% ")), " in this use case because ", AS25, " ", AT25, " ", AU25, " ", AV25, " ", AW25, " has/have NA values in it") -> Readjusted weights: :30% :40% :30% in this use case because has/have NA values in it | AS25: =IF(C25="NA", C$10,"") | AT25: =IF(D25="NA", D$10,"") | AU25: =IF(E25="NA", E$10,"") | AV25: =IF(F25="NA", F$10,"") | AW25: =IF(G25="NA", G$10,"") | AX25: =SUMPRODUCT(C25:G25,AL25:AP25) -> 0 | AY25: =SUMPRODUCT(I25:M25,Y25:AC25) -> 0
A26: ='Step 1 - Fill in Details'!C22 -> UC16 | B26: ='Step 1 - Fill in Details'!D22 -> FALSE | O26: =AX26 -> 0 | P26: =AY26 -> 0 | Q26: {=P26+O26+(RAND()*0.00000000000001+1/ROW(16:16)*0.000001)} -> 6.2500005e-08 | R26: =AND(P26=0,O26=0) -> TRUE | S26: {=SUMPRODUCT(($R$11:R26)*1)} -> 14 | U26: =AND(O26=0,P26=0) -> TRUE | V26: {=SUMPRODUCT(($U$10:U26)*1)} -> 14 | X26: {=SUMPRODUCT($I$10:$M$10,(I26:M26<>"NA")*1)} -> 1 | Y26: =IF(I26="NA",0,I$10/$X26) -> 0.3 | Z26: =IF(J26="NA",0,J$10/$X26) -> 0.4 | AA26: =IF(K26="NA",0,K$10/$X26) -> 0.3 | AB26: =IF(L26="NA",0,L$10/$X26) -> 0 | AC26: =IF(M26="NA",0,M$10/$X26) -> 0 | AD26: =IF(X26<1, AE26, "") | AE26: =CONCATENATE("Readjusted weights: ", IF(Y26=0, " ", CONCATENATE($J$8, ":", Y26*100, "% ")), IF(Z26=0, " ", CONCATENATE($K$8, ":", Z26*100, "% ")), IF(AA26=0, " ", CONCATENATE($L$8, ":", AA26*100, "% ")), IF(AB26=0, " ", CONCATENATE($M$8, ":", AB26*100, "% ")), IF(AC26=0, " ", CONCATENATE($N$8, ":", AC26*100, "% ")), " in this use case because ", AF26, " ", AG26, " ", AH26, " ", AI26, " ", AJ26, " has/have NA values in it") -> Readjusted weights: :30% :40% :30% in this use case because has/have NA values in it | AF26: =IF(J26="NA", $J$8,"") | AG26: =IF(K26="NA", $J$8,"") | AH26: =IF(L26="NA", $J$8,"") | AI26: =IF(M26="NA", $J$8,"") | AJ26: =IF(N26="NA", $J$8,"") | AK26: {=SUMPRODUCT($C$10:$G$10,(C26:G26<>"NA")*1)} -> 1 | AL26: =IF(C26="NA",0,C$10/$AK26) -> 0.3 | AM26: =IF(D26="NA",0,D$10/$AK26) -> 0.4 | AN26: =IF(E26="NA",0,E$10/$AK26) -> 0.3 | AO26: =IF(F26="NA",0,F$10/$AK26) -> 0 | AP26: =IF(G26="NA",0,G$10/$AK26) -> 0 | AQ26: =IF(AK26<1, AR26, "") | AR26: =CONCATENATE("Readjusted weights: ", IF(AL26=0, " ", CONCATENATE($D$8, ":", AL26*100, "% ")), IF(AM26=0, " ", CONCATENATE($E$8, ":", AM26*100, "% ")), IF(AN26=0, " ", CONCATENATE($F$8, ":", AN26*100, "% ")), IF(AO26=0, " ", CONCATENATE($G$8, ":", AO26*100, "% ")), IF(AP26=0, " ", CONCATENATE($H$8, ":", AP26*100, "% ")), " in this use case because ", AS26, " ", AT26, " ", AU26, " ", AV26, " ", AW26, " has/have NA values in it") -> Readjusted weights: :30% :40% :30% in this use case because has/have NA values in it | AS26: =IF(C26="NA", C$10,"") | AT26: =IF(D26="NA", D$10,"") | AU26: =IF(E26="NA", E$10,"") | AV26: =IF(F26="NA", F$10,"") | AW26: =IF(G26="NA", G$10,"") | AX26: =SUMPRODUCT(C26:G26,AL26:AP26) -> 0 | AY26: =SUMPRODUCT(I26:M26,Y26:AC26) -> 0
A27: ='Step 1 - Fill in Details'!C23 -> UC17 | B27: ='Step 1 - Fill in Details'!D23 -> FALSE | O27: =AX27 -> 0 | P27: =AY27 -> 0 | Q27: {=P27+O27+(RAND()*0.00000000000001+1/ROW(17:17)*0.000001)} -> 5.8823536e-08 | R27: =AND(P27=0,O27=0) -> TRUE | S27: {=SUMPRODUCT(($R$11:R27)*1)} -> 15 | U27: =AND(O27=0,P27=0) -> TRUE | V27: {=SUMPRODUCT(($U$10:U27)*1)} -> 15 | X27: {=SUMPRODUCT($I$10:$M$10,(I27:M27<>"NA")*1)} -> 1 | Y27: =IF(I27="NA",0,I$10/$X27) -> 0.3 | Z27: =IF(J27="NA",0,J$10/$X27) -> 0.4 | AA27: =IF(K27="NA",0,K$10/$X27) -> 0.3 | AB27: =IF(L27="NA",0,L$10/$X27) -> 0 | AC27: =IF(M27="NA",0,M$10/$X27) -> 0 | AD27: =IF(X27<1, AE27, "") | AE27: =CONCATENATE("Readjusted weights: ", IF(Y27=0, " ", CONCATENATE($J$8, ":", Y27*100, "% ")), IF(Z27=0, " ", CONCATENATE($K$8, ":", Z27*100, "% ")), IF(AA27=0, " ", CONCATENATE($L$8, ":", AA27*100, "% ")), IF(AB27=0, " ", CONCATENATE($M$8, ":", AB27*100, "% ")), IF(AC27=0, " ", CONCATENATE($N$8, ":", AC27*100, "% ")), " in this use case because ", AF27, " ", AG27, " ", AH27, " ", AI27, " ", AJ27, " has/have NA values in it") -> Readjusted weights: :30% :40% :30% in this use case because has/have NA values in it | AF27: =IF(J27="NA", $J$8,"") | AG27: =IF(K27="NA", $J$8,"") | AH27: =IF(L27="NA", $J$8,"") | AI27: =IF(M27="NA", $J$8,"") | AJ27: =IF(N27="NA", $J$8,"") | AK27: {=SUMPRODUCT($C$10:$G$10,(C27:G27<>"NA")*1)} -> 1 | AL27: =IF(C27="NA",0,C$10/$AK27) -> 0.3 | AM27: =IF(D27="NA",0,D$10/$AK27) -> 0.4 | AN27: =IF(E27="NA",0,E$10/$AK27) -> 0.3 | AO27: =IF(F27="NA",0,F$10/$AK27) -> 0 | AP27: =IF(G27="NA",0,G$10/$AK27) -> 0 | AQ27: =IF(AK27<1, AR27, "") | AR27: =CONCATENATE("Readjusted weights: ", IF(AL27=0, " ", CONCATENATE($D$8, ":", AL27*100, "% ")), IF(AM27=0, " ", CONCATENATE($E$8, ":", AM27*100, "% ")), IF(AN27=0, " ", CONCATENATE($F$8, ":", AN27*100, "% ")), IF(AO27=0, " ", CONCATENATE($G$8, ":", AO27*100, "% ")), IF(AP27=0, " ", CONCATENATE($H$8, ":", AP27*100, "% ")), " in this use case because ", AS27, " ", AT27, " ", AU27, " ", AV27, " ", AW27, " has/have NA values in it") -> Readjusted weights: :30% :40% :30% in this use case because has/have NA values in it | AS27: =IF(C27="NA", C$10,"") | AT27: =IF(D27="NA", D$10,"") | AU27: =IF(E27="NA", E$10,"") | AV27: =IF(F27="NA", F$10,"") | AW27: =IF(G27="NA", G$10,"") | AX27: =SUMPRODUCT(C27:G27,AL27:AP27) -> 0 | AY27: =SUMPRODUCT(I27:M27,Y27:AC27) -> 0
A28: ='Step 1 - Fill in Details'!C24 -> UC18 | B28: ='Step 1 - Fill in Details'!D24 -> FALSE | O28: =AX28 -> 0 | P28: =AY28 -> 0 | Q28: {=P28+O28+(RAND()*0.00000000000001+1/ROW(18:18)*0.000001)} -> 5.5555558e-08 | R28: =AND(P28=0,O28=0) -> TRUE | S28: {=SUMPRODUCT(($R$11:R28)*1)} -> 16 | U28: =AND(O28=0,P28=0) -> TRUE | V28: {=SUMPRODUCT(($U$10:U28)*1)} -> 16 | X28: {=SUMPRODUCT($I$10:$M$10,(I28:M28<>"NA")*1)} -> 1 | Y28: =IF(I28="NA",0,I$10/$X28) -> 0.3 | Z28: =IF(J28="NA",0,J$10/$X28) -> 0.4 | AA28: =IF(K28="NA",0,K$10/$X28) -> 0.3 | AB28: =IF(L28="NA",0,L$10/$X28) -> 0 | AC28: =IF(M28="NA",0,M$10/$X28) -> 0 | AD28: =IF(X28<1, AE28, "") | AE28: =CONCATENATE("Readjusted weights: ", IF(Y28=0, " ", CONCATENATE($J$8, ":", Y28*100, "% ")), IF(Z28=0, " ", CONCATENATE($K$8, ":", Z28*100, "% ")), IF(AA28=0, " ", CONCATENATE($L$8, ":", AA28*100, "% ")), IF(AB28=0, " ", CONCATENATE($M$8, ":", AB28*100, "% ")), IF(AC28=0, " ", CONCATENATE($N$8, ":", AC28*100, "% ")), " in this use case because ", AF28, " ", AG28, " ", AH28, " ", AI28, " ", AJ28, " has/have NA values in it") -> Readjusted weights: :30% :40% :30% in this use case because has/have NA values in it | AF28: =IF(J28="NA", $J$8,"") | AG28: =IF(K28="NA", $J$8,"") | AH28: =IF(L28="NA", $J$8,"") | AI28: =IF(M28="NA", $J$8,"") | AJ28: =IF(N28="NA", $J$8,"") | AK28: {=SUMPRODUCT($C$10:$G$10,(C28:G28<>"NA")*1)} -> 1 | AL28: =IF(C28="NA",0,C$10/$AK28) -> 0.3 | AM28: =IF(D28="NA",0,D$10/$AK28) -> 0.4 | AN28: =IF(E28="NA",0,E$10/$AK28) -> 0.3 | AO28: =IF(F28="NA",0,F$10/$AK28) -> 0 | AP28: =IF(G28="NA",0,G$10/$AK28) -> 0 | AQ28: =IF(AK28<1, AR28, "") | AR28: =CONCATENATE("Readjusted weights: ", IF(AL28=0, " ", CONCATENATE($D$8, ":", AL28*100, "% ")), IF(AM28=0, " ", CONCATENATE($E$8, ":", AM28*100, "% ")), IF(AN28=0, " ", CONCATENATE($F$8, ":", AN28*100, "% ")), IF(AO28=0, " ", CONCATENATE($G$8, ":", AO28*100, "% ")), IF(AP28=0, " ", CONCATENATE($H$8, ":", AP28*100, "% ")), " in this use case because ", AS28, " ", AT28, " ", AU28, " ", AV28, " ", AW28, " has/have NA values in it") -> Readjusted weights: :30% :40% :30% in this use case because has/have NA values in it | AS28: =IF(C28="NA", C$10,"") | AT28: =IF(D28="NA", D$10,"") | AU28: =IF(E28="NA", E$10,"") | AV28: =IF(F28="NA", F$10,"") | AW28: =IF(G28="NA", G$10,"") | AX28: =SUMPRODUCT(C28:G28,AL28:AP28) -> 0 | AY28: =SUMPRODUCT(I28:M28,Y28:AC28) -> 0
A29: ='Step 1 - Fill in Details'!C25 -> UC19 | B29: ='Step 1 - Fill in Details'!D25 -> FALSE | O29: =AX29 -> 0 | P29: =AY29 -> 0 | Q29: {=P29+O29+(RAND()*0.00000000000001+1/ROW(19:19)*0.000001)} -> 5.2631582e-08 | R29: =AND(P29=0,O29=0) -> TRUE | S29: {=SUMPRODUCT(($R$11:R29)*1)} -> 17 | U29: =AND(O29=0,P29=0) -> TRUE | V29: {=SUMPRODUCT(($U$10:U29)*1)} -> 17 | X29: {=SUMPRODUCT($I$10:$M$10,(I29:M29<>"NA")*1)} -> 1 | Y29: =IF(I29="NA",0,I$10/$X29) -> 0.3 | Z29: =IF(J29="NA",0,J$10/$X29) -> 0.4 | AA29: =IF(K29="NA",0,K$10/$X29) -> 0.3 | AB29: =IF(L29="NA",0,L$10/$X29) -> 0 | AC29: =IF(M29="NA",0,M$10/$X29) -> 0 | AD29: =IF(X29<1, AE29, "") | AE29: =CONCATENATE("Readjusted weights: ", IF(Y29=0, " ", CONCATENATE($J$8, ":", Y29*100, "% ")), IF(Z29=0, " ", CONCATENATE($K$8, ":", Z29*100, "% ")), IF(AA29=0, " ", CONCATENATE($L$8, ":", AA29*100, "% ")), IF(AB29=0, " ", CONCATENATE($M$8, ":", AB29*100, "% ")), IF(AC29=0, " ", CONCATENATE($N$8, ":", AC29*100, "% ")), " in this use case because ", AF29, " ", AG29, " ", AH29, " ", AI29, " ", AJ29, " has/have NA values in it") -> Readjusted weights: :30% :40% :30% in this use case because has/have NA values in it | AF29: =IF(J29="NA", $J$8,"") | AG29: =IF(K29="NA", $J$8,"") | AH29: =IF(L29="NA", $J$8,"") | AI29: =IF(M29="NA", $J$8,"") | AJ29: =IF(N29="NA", $J$8,"") | AK29: {=SUMPRODUCT($C$10:$G$10,(C29:G29<>"NA")*1)} -> 1 | AL29: =IF(C29="NA",0,C$10/$AK29) -> 0.3 | AM29: =IF(D29="NA",0,D$10/$AK29) -> 0.4 | AN29: =IF(E29="NA",0,E$10/$AK29) -> 0.3 | AO29: =IF(F29="NA",0,F$10/$AK29) -> 0 | AP29: =IF(G29="NA",0,G$10/$AK29) -> 0 | AQ29: =IF(AK29<1, AR29, "") | AR29: =CONCATENATE("Readjusted weights: ", IF(AL29=0, " ", CONCATENATE($D$8, ":", AL29*100, "% ")), IF(AM29=0, " ", CONCATENATE($E$8, ":", AM29*100, "% ")), IF(AN29=0, " ", CONCATENATE($F$8, ":", AN29*100, "% ")), IF(AO29=0, " ", CONCATENATE($G$8, ":", AO29*100, "% ")), IF(AP29=0, " ", CONCATENATE($H$8, ":", AP29*100, "% ")), " in this use case because ", AS29, " ", AT29, " ", AU29, " ", AV29, " ", AW29, " has/have NA values in it") -> Readjusted weights: :30% :40% :30% in this use case because has/have NA values in it | AS29: =IF(C29="NA", C$10,"") | AT29: =IF(D29="NA", D$10,"") | AU29: =IF(E29="NA", E$10,"") | AV29: =IF(F29="NA", F$10,"") | AW29: =IF(G29="NA", G$10,"") | AX29: =SUMPRODUCT(C29:G29,AL29:AP29) -> 0 | AY29: =SUMPRODUCT(I29:M29,Y29:AC29) -> 0
A30: ='Step 1 - Fill in Details'!C26 -> UC20 | B30: ='Step 1 - Fill in Details'!D26 -> FALSE | O30: =AX30 -> 0 | P30: =AY30 -> 0 | Q30: {=P30+O30+(RAND()*0.00000000000001+1/ROW(20:20)*0.000001)} -> 5.0000009e-08 | R30: =AND(P30=0,O30=0) -> TRUE | S30: {=SUMPRODUCT(($R$11:R30)*1)} -> 18 | U30: =AND(O30=0,P30=0) -> TRUE | V30: {=SUMPRODUCT(($U$10:U30)*1)} -> 18 | X30: {=SUMPRODUCT($I$10:$M$10,(I30:M30<>"NA")*1)} -> 1 | Y30: =IF(I30="NA",0,I$10/$X30) -> 0.3 | Z30: =IF(J30="NA",0,J$10/$X30) -> 0.4 | AA30: =IF(K30="NA",0,K$10/$X30) -> 0.3 | AB30: =IF(L30="NA",0,L$10/$X30) -> 0 | AC30: =IF(M30="NA",0,M$10/$X30) -> 0 | AD30: =IF(X30<1, AE30, "") | AE30: =CONCATENATE("Readjusted weights: ", IF(Y30=0, " ", CONCATENATE($J$8, ":", Y30*100, "% ")), IF(Z30=0, " ", CONCATENATE($K$8, ":", Z30*100, "% ")), IF(AA30=0, " ", CONCATENATE($L$8, ":", AA30*100, "% ")), IF(AB30=0, " ", CONCATENATE($M$8, ":", AB30*100, "% ")), IF(AC30=0, " ", CONCATENATE($N$8, ":", AC30*100, "% ")), " in this use case because ", AF30, " ", AG30, " ", AH30, " ", AI30, " ", AJ30, " has/have NA values in it") -> Readjusted weights: :30% :40% :30% in this use case because has/have NA values in it | AF30: =IF(J30="NA", $J$8,"") | AG30: =IF(K30="NA", $J$8,"") | AH30: =IF(L30="NA", $J$8,"") | AI30: =IF(M30="NA", $J$8,"") | AJ30: =IF(N30="NA", $J$8,"") | AK30: {=SUMPRODUCT($C$10:$G$10,(C30:G30<>"NA")*1)} -> 1 | AL30: =IF(C30="NA",0,C$10/$AK30) -> 0.3 | AM30: =IF(D30="NA",0,D$10/$AK30) -> 0.4 | AN30: =IF(E30="NA",0,E$10/$AK30) -> 0.3 | AO30: =IF(F30="NA",0,F$10/$AK30) -> 0 | AP30: =IF(G30="NA",0,G$10/$AK30) -> 0 | AQ30: =IF(AK30<1, AR30, "") | AR30: =CONCATENATE("Readjusted weights: ", IF(AL30=0, " ", CONCATENATE($D$8, ":", AL30*100, "% ")), IF(AM30=0, " ", CONCATENATE($E$8, ":", AM30*100, "% ")), IF(AN30=0, " ", CONCATENATE($F$8, ":", AN30*100, "% ")), IF(AO30=0, " ", CONCATENATE($G$8, ":", AO30*100, "% ")), IF(AP30=0, " ", CONCATENATE($H$8, ":", AP30*100, "% ")), " in this use case because ", AS30, " ", AT30, " ", AU30, " ", AV30, " ", AW30, " has/have NA values in it") -> Readjusted weights: :30% :40% :30% in this use case because has/have NA values in it | AS30: =IF(C30="NA", C$10,"") | AT30: =IF(D30="NA", D$10,"") | AU30: =IF(E30="NA", E$10,"") | AV30: =IF(F30="NA", F$10,"") | AW30: =IF(G30="NA", G$10,"") | AX30: =SUMPRODUCT(C30:G30,AL30:AP30) -> 0 | AY30: =SUMPRODUCT(I30:M30,Y30:AC30) -> 0
